{
 "cells": [
  {
   "cell_type": "code",
   "execution_count": 3,
   "id": "aa9ac6c5",
   "metadata": {},
   "outputs": [],
   "source": [
    "import mysql.connector\n",
    "from mysql.connector.constants import ClientFlag"
   ]
  },
  {
   "cell_type": "code",
   "execution_count": 5,
   "id": "82b82c46",
   "metadata": {},
   "outputs": [],
   "source": [
    "config = {\n",
    "    'user': 'root',\n",
    "    'password': 'batman123jock',\n",
    "    'host': '34.79.20.30',\n",
    "    'client_flags': [ClientFlag.SSL],\n",
    "    'ssl_ca': 'env/server-ca.pem',\n",
    "    'ssl_cert': 'env/client-cert.pem',\n",
    "    'ssl_key': 'env/client-key.pem'\n",
    "}"
   ]
  },
  {
   "cell_type": "code",
   "execution_count": 8,
   "id": "8d817fa6",
   "metadata": {},
   "outputs": [
    {
     "ename": "InterfaceError",
     "evalue": "2003: Can't connect to MySQL server on '34.79.20.30:3306' (60 Operation timed out)",
     "output_type": "error",
     "traceback": [
      "\u001b[0;31m---------------------------------------------------------------------------\u001b[0m",
      "\u001b[0;31mTimeoutError\u001b[0m                              Traceback (most recent call last)",
      "File \u001b[0;32m/Library/Frameworks/Python.framework/Versions/3.9/lib/python3.9/site-packages/mysql/connector/network.py:574\u001b[0m, in \u001b[0;36mMySQLTCPSocket.open_connection\u001b[0;34m(self)\u001b[0m\n\u001b[1;32m    573\u001b[0m     \u001b[38;5;28mself\u001b[39m\u001b[38;5;241m.\u001b[39msock\u001b[38;5;241m.\u001b[39msettimeout(\u001b[38;5;28mself\u001b[39m\u001b[38;5;241m.\u001b[39m_connection_timeout)\n\u001b[0;32m--> 574\u001b[0m     \u001b[38;5;28;43mself\u001b[39;49m\u001b[38;5;241;43m.\u001b[39;49m\u001b[43msock\u001b[49m\u001b[38;5;241;43m.\u001b[39;49m\u001b[43mconnect\u001b[49m\u001b[43m(\u001b[49m\u001b[43msockaddr\u001b[49m\u001b[43m)\u001b[49m\n\u001b[1;32m    575\u001b[0m \u001b[38;5;28;01mexcept\u001b[39;00m \u001b[38;5;167;01mIOError\u001b[39;00m \u001b[38;5;28;01mas\u001b[39;00m err:\n",
      "\u001b[0;31mTimeoutError\u001b[0m: [Errno 60] Operation timed out",
      "\nDuring handling of the above exception, another exception occurred:\n",
      "\u001b[0;31mInterfaceError\u001b[0m                            Traceback (most recent call last)",
      "Input \u001b[0;32mIn [8]\u001b[0m, in \u001b[0;36m<module>\u001b[0;34m\u001b[0m\n\u001b[1;32m      1\u001b[0m \u001b[38;5;66;03m# now we establish our connection\u001b[39;00m\n\u001b[0;32m----> 2\u001b[0m cnxn \u001b[38;5;241m=\u001b[39m \u001b[43mmysql\u001b[49m\u001b[38;5;241;43m.\u001b[39;49m\u001b[43mconnector\u001b[49m\u001b[38;5;241;43m.\u001b[39;49m\u001b[43mconnect\u001b[49m\u001b[43m(\u001b[49m\u001b[38;5;241;43m*\u001b[39;49m\u001b[38;5;241;43m*\u001b[39;49m\u001b[43mconfig\u001b[49m\u001b[43m)\u001b[49m\n",
      "File \u001b[0;32m/Library/Frameworks/Python.framework/Versions/3.9/lib/python3.9/site-packages/mysql/connector/__init__.py:273\u001b[0m, in \u001b[0;36mconnect\u001b[0;34m(*args, **kwargs)\u001b[0m\n\u001b[1;32m    271\u001b[0m \u001b[38;5;28;01mif\u001b[39;00m HAVE_CEXT \u001b[38;5;129;01mand\u001b[39;00m \u001b[38;5;129;01mnot\u001b[39;00m use_pure:\n\u001b[1;32m    272\u001b[0m     \u001b[38;5;28;01mreturn\u001b[39;00m CMySQLConnection(\u001b[38;5;241m*\u001b[39margs, \u001b[38;5;241m*\u001b[39m\u001b[38;5;241m*\u001b[39mkwargs)\n\u001b[0;32m--> 273\u001b[0m \u001b[38;5;28;01mreturn\u001b[39;00m \u001b[43mMySQLConnection\u001b[49m\u001b[43m(\u001b[49m\u001b[38;5;241;43m*\u001b[39;49m\u001b[43margs\u001b[49m\u001b[43m,\u001b[49m\u001b[43m \u001b[49m\u001b[38;5;241;43m*\u001b[39;49m\u001b[38;5;241;43m*\u001b[39;49m\u001b[43mkwargs\u001b[49m\u001b[43m)\u001b[49m\n",
      "File \u001b[0;32m/Library/Frameworks/Python.framework/Versions/3.9/lib/python3.9/site-packages/mysql/connector/connection.py:116\u001b[0m, in \u001b[0;36mMySQLConnection.__init__\u001b[0;34m(self, *args, **kwargs)\u001b[0m\n\u001b[1;32m    114\u001b[0m \u001b[38;5;28;01mif\u001b[39;00m kwargs:\n\u001b[1;32m    115\u001b[0m     \u001b[38;5;28;01mtry\u001b[39;00m:\n\u001b[0;32m--> 116\u001b[0m         \u001b[38;5;28;43mself\u001b[39;49m\u001b[38;5;241;43m.\u001b[39;49m\u001b[43mconnect\u001b[49m\u001b[43m(\u001b[49m\u001b[38;5;241;43m*\u001b[39;49m\u001b[38;5;241;43m*\u001b[39;49m\u001b[43mkwargs\u001b[49m\u001b[43m)\u001b[49m\n\u001b[1;32m    117\u001b[0m     \u001b[38;5;28;01mexcept\u001b[39;00m:\n\u001b[1;32m    118\u001b[0m         \u001b[38;5;66;03m# Tidy-up underlying socket on failure\u001b[39;00m\n\u001b[1;32m    119\u001b[0m         \u001b[38;5;28mself\u001b[39m\u001b[38;5;241m.\u001b[39mclose()\n",
      "File \u001b[0;32m/Library/Frameworks/Python.framework/Versions/3.9/lib/python3.9/site-packages/mysql/connector/abstracts.py:1052\u001b[0m, in \u001b[0;36mMySQLConnectionAbstract.connect\u001b[0;34m(self, **kwargs)\u001b[0m\n\u001b[1;32m   1049\u001b[0m     \u001b[38;5;28mself\u001b[39m\u001b[38;5;241m.\u001b[39mconfig(\u001b[38;5;241m*\u001b[39m\u001b[38;5;241m*\u001b[39mkwargs)\n\u001b[1;32m   1051\u001b[0m \u001b[38;5;28mself\u001b[39m\u001b[38;5;241m.\u001b[39mdisconnect()\n\u001b[0;32m-> 1052\u001b[0m \u001b[38;5;28;43mself\u001b[39;49m\u001b[38;5;241;43m.\u001b[39;49m\u001b[43m_open_connection\u001b[49m\u001b[43m(\u001b[49m\u001b[43m)\u001b[49m\n\u001b[1;32m   1053\u001b[0m \u001b[38;5;66;03m# Server does not allow to run any other statement different from ALTER\u001b[39;00m\n\u001b[1;32m   1054\u001b[0m \u001b[38;5;66;03m# when user's password has been expired.\u001b[39;00m\n\u001b[1;32m   1055\u001b[0m \u001b[38;5;28;01mif\u001b[39;00m \u001b[38;5;129;01mnot\u001b[39;00m \u001b[38;5;28mself\u001b[39m\u001b[38;5;241m.\u001b[39m_client_flags \u001b[38;5;241m&\u001b[39m ClientFlag\u001b[38;5;241m.\u001b[39mCAN_HANDLE_EXPIRED_PASSWORDS:\n",
      "File \u001b[0;32m/Library/Frameworks/Python.framework/Versions/3.9/lib/python3.9/site-packages/mysql/connector/connection.py:494\u001b[0m, in \u001b[0;36mMySQLConnection._open_connection\u001b[0;34m(self)\u001b[0m\n\u001b[1;32m    492\u001b[0m \u001b[38;5;28mself\u001b[39m\u001b[38;5;241m.\u001b[39m_socket \u001b[38;5;241m=\u001b[39m \u001b[38;5;28mself\u001b[39m\u001b[38;5;241m.\u001b[39m_get_connection()\n\u001b[1;32m    493\u001b[0m \u001b[38;5;28;01mtry\u001b[39;00m:\n\u001b[0;32m--> 494\u001b[0m     \u001b[38;5;28;43mself\u001b[39;49m\u001b[38;5;241;43m.\u001b[39;49m\u001b[43m_socket\u001b[49m\u001b[38;5;241;43m.\u001b[39;49m\u001b[43mopen_connection\u001b[49m\u001b[43m(\u001b[49m\u001b[43m)\u001b[49m\n\u001b[1;32m    495\u001b[0m     \u001b[38;5;28mself\u001b[39m\u001b[38;5;241m.\u001b[39m_do_handshake()\n\u001b[1;32m    496\u001b[0m     \u001b[38;5;28mself\u001b[39m\u001b[38;5;241m.\u001b[39m_do_auth(\u001b[38;5;28mself\u001b[39m\u001b[38;5;241m.\u001b[39m_user, \u001b[38;5;28mself\u001b[39m\u001b[38;5;241m.\u001b[39m_password,\n\u001b[1;32m    497\u001b[0m                   \u001b[38;5;28mself\u001b[39m\u001b[38;5;241m.\u001b[39m_database, \u001b[38;5;28mself\u001b[39m\u001b[38;5;241m.\u001b[39m_client_flags, \u001b[38;5;28mself\u001b[39m\u001b[38;5;241m.\u001b[39m_charset_id,\n\u001b[1;32m    498\u001b[0m                   \u001b[38;5;28mself\u001b[39m\u001b[38;5;241m.\u001b[39m_ssl, \u001b[38;5;28mself\u001b[39m\u001b[38;5;241m.\u001b[39m_conn_attrs)\n",
      "File \u001b[0;32m/Library/Frameworks/Python.framework/Versions/3.9/lib/python3.9/site-packages/mysql/connector/network.py:576\u001b[0m, in \u001b[0;36mMySQLTCPSocket.open_connection\u001b[0;34m(self)\u001b[0m\n\u001b[1;32m    574\u001b[0m     \u001b[38;5;28mself\u001b[39m\u001b[38;5;241m.\u001b[39msock\u001b[38;5;241m.\u001b[39mconnect(sockaddr)\n\u001b[1;32m    575\u001b[0m \u001b[38;5;28;01mexcept\u001b[39;00m \u001b[38;5;167;01mIOError\u001b[39;00m \u001b[38;5;28;01mas\u001b[39;00m err:\n\u001b[0;32m--> 576\u001b[0m     \u001b[38;5;28;01mraise\u001b[39;00m errors\u001b[38;5;241m.\u001b[39mInterfaceError(\n\u001b[1;32m    577\u001b[0m         errno\u001b[38;5;241m=\u001b[39m\u001b[38;5;241m2003\u001b[39m, values\u001b[38;5;241m=\u001b[39m(\n\u001b[1;32m    578\u001b[0m             \u001b[38;5;28mself\u001b[39m\u001b[38;5;241m.\u001b[39mserver_host,\n\u001b[1;32m    579\u001b[0m             \u001b[38;5;28mself\u001b[39m\u001b[38;5;241m.\u001b[39mserver_port,\n\u001b[1;32m    580\u001b[0m             _strioerror(err),\n\u001b[1;32m    581\u001b[0m         )\n\u001b[1;32m    582\u001b[0m     )\n\u001b[1;32m    583\u001b[0m \u001b[38;5;28;01mexcept\u001b[39;00m \u001b[38;5;167;01mException\u001b[39;00m \u001b[38;5;28;01mas\u001b[39;00m err:\n\u001b[1;32m    584\u001b[0m     \u001b[38;5;28;01mraise\u001b[39;00m errors\u001b[38;5;241m.\u001b[39mOperationalError(\u001b[38;5;28mstr\u001b[39m(err))\n",
      "\u001b[0;31mInterfaceError\u001b[0m: 2003: Can't connect to MySQL server on '34.79.20.30:3306' (60 Operation timed out)"
     ]
    }
   ],
   "source": [
    "# now we establish our connection\n",
    "cnxn = mysql.connector.connect(**config)"
   ]
  },
  {
   "cell_type": "code",
   "execution_count": 7,
   "id": "4317f196",
   "metadata": {},
   "outputs": [
    {
     "data": {
      "text/plain": [
       "'/Users/matt/Documents/fp_code'"
      ]
     },
     "execution_count": 7,
     "metadata": {},
     "output_type": "execute_result"
    }
   ],
   "source": [
    "%pwd"
   ]
  },
  {
   "cell_type": "code",
   "execution_count": null,
   "id": "09fc386a",
   "metadata": {},
   "outputs": [],
   "source": []
  }
 ],
 "metadata": {
  "kernelspec": {
   "display_name": "Python 3 (ipykernel)",
   "language": "python",
   "name": "python3"
  },
  "language_info": {
   "codemirror_mode": {
    "name": "ipython",
    "version": 3
   },
   "file_extension": ".py",
   "mimetype": "text/x-python",
   "name": "python",
   "nbconvert_exporter": "python",
   "pygments_lexer": "ipython3",
   "version": "3.9.4"
  }
 },
 "nbformat": 4,
 "nbformat_minor": 5
}
